Workbook

Sheet 社保费用计算表
B2: 社保费用计算表 制作：ZJHCOFI
B3: ●参考文献：《关于公布2025年职工基本养老保险缴费基数上下限和基本养老金计发基数有关问题的通知》 https://hrss.gd.gov.cn/zwgk/gsgg/content/post_4789648.html ●社保缴费明细查询（广东）： https://ggfw.hrss.gd.gov.cn/gdggfw/theme-service-module/service-menus?moduleId=2
B4: 当前计算标准（2026年，广州，普通企业在职职工）： 1、企业职工基本养老保险缴费基数：下限 5510 元，上限 27549 元 2、企业职工基本养老保险缴费比例，单位比例：16%，个人比例：8% 3、失业保险缴费基数：下限 2500 元，上限 41112 元 4、失业保险缴费比例，单位比例：0.8%，个人比例：0.2% 5、工伤保险缴费基数：下限 2500 元，按行业风险浮动； 6、工伤保险缴费比例，单位比例：0.2%–1.4%（分 8 档），个人不需要缴纳
B5: 以下淡蓝色底的表格可以手动输入内容
B6: 养老保险缴费基数 | C6: 5500 | D6: 单位缴费比例 | E6: 0.16 | F6: 个人缴费比例 | G6: 0.08
B7: 失业保险缴费基数 | C7: 5500 | D7: 单位缴费比例 | E7: 0.008 | F7: 个人缴费比例 | G7: 0.002
B8: 工伤保险缴费基数 | C8: 5500 | D8: 单位缴费比例 | E8: 0.004
B9: 基本养老保险合计缴纳金额 | C9: =E9+G9 -> 1320 | D9: 基本养老保险单位缴纳金额 | E9: =C6*E6 -> 880 | F9: 基本养老保险个人缴纳金额 | G9: =C6*G6 -> 440
B10: 失业保险合计缴纳金额 | C10: =E10+G10 -> 55 | D10: 失业保险单位缴纳金额 | E10: =C7*E7 -> 44 | F10: 失业保险个人缴纳金额 | G10: =C7*G7 -> 11
B11: 工伤保险合计缴纳金额 | C11: =E11 -> 22 | D11: 工伤保险单位缴纳金额 | E11: =C8*E8 -> 22
B12: 月总计 | C12: =E12+G12 -> 1397 | D12: 单位缴纳总金额 | E12: =SUM(E9:E11) -> 946 | F12: 个人缴纳总金额 | G12: =SUM(G9:G11) -> 451
B13: 每年普调缴费基数时，相较于上一年的涨幅 （根据个人情况填写，不懂可以看最下方的规则） | D13: 0.03 | E13: 缴纳社保年数 （根据个人情况填写） | G13: 20
B14: 缴够年数后的社保总缴纳金额 | D14: =VLOOKUP(社保费用计算表!G13,每年金额计算!B:D,3,0) -> 463968.61 | E14: 法定退休年龄 | G14: 63
B15: 刚退休时的退休金金额(月) | D15: 1600 | E15: 每年退休金，相较于上一年的涨幅 | G15: 0.02
B16: 回本岁数 | E16: =IFERROR(INDEX(每年金额计算!E3:E362, MATCH("回本", 每年金额计算!A3:A362, 0)), 0)+G14 -> 83
B17: 第二年缴费基数普调规则： 1. 调整时间周期 广州企业职工养老 / 失业 / 工伤每年 7 月统一调整一次基数，执行周期：当年 7 月 — 次年 6 月；一年仅一次年度普调，中途不改动。 2. 基数计算公式（第二年核定逻辑） 情况 1：入职满完整 12 个月（次年普调标准算法） 新缴费基数 = 上一自然年度（1–12 月）全部工资性总收入 ÷ 12 工资性收入包含：基本工资、绩效、全勤、交通 / 餐补、加班费、季度奖、年终奖、提成等全部税前劳动报酬，不含个税、个人社保公积金扣除额。 举例：员工当年每月应发 5500，年终奖金 6000 全年总收入 = 5500×12+6000=72000 次年新基数 = 72000÷12=6000 元 情况 2：入职未满完整 12 个月（入职当年次年 7 月调基数） 基数 = 入职后实际发放月份全部工资总额 ÷ 实际在岗月数 例：8 月入职，当年只发 5 个月工资，总发放 30000，次年基数 = 30000÷5=6000 元

Sheet 每年金额计算
B1: 社保缴费金额计算 | E1: 退休金金额计算
A2: 判断 | B2: 缴费年数 | C2: 当年缴费金额 | D2: 累计缴费金额 | E2: 发放年数 | F2: 当年发放金额 | G2: 累计发放金额
A3: =IF(G3>社保费用计算表!D14,"回本","亏本") -> 亏本 | B3: 1 | C3: =(社保费用计算表!C12*12)*(1+社保费用计算表!D13)^每年金额计算!B3 -> 17266.92 | D3: =SUM($C$3:C3) -> 17266.92 | E3: 1 | F3: =(社保费用计算表!D15*12)*(1+社保费用计算表!G15)^每年金额计算!E3 -> 19584 | G3: =SUM($F$3:F3) -> 19584
A4: =IF(G4>社保费用计算表!D14,"回本","亏本") -> 亏本 | B4: 2 | C4: =(社保费用计算表!C12*12)*(1+社保费用计算表!D13)^每年金额计算!B4 -> 17784.928 | D4: =SUM($C$3:C4) -> 35051.848 | E4: 2 | F4: =(社保费用计算表!D15*12)*(1+社保费用计算表!G15)^每年金额计算!E4 -> 19975.68 | G4: =SUM($F$3:F4) -> 39559.68
A5: =IF(G5>社保费用计算表!D14,"回本","亏本") -> 亏本 | B5: 3 | C5: =(社保费用计算表!C12*12)*(1+社保费用计算表!D13)^每年金额计算!B5 -> 18318.475 | D5: =SUM($C$3:C5) -> 53370.323 | E5: 3 | F5: =(社保费用计算表!D15*12)*(1+社保费用计算表!G15)^每年金额计算!E5 -> 20375.194 | G5: =SUM($F$3:F5) -> 59934.874
A6: =IF(G6>社保费用计算表!D14,"回本","亏本") -> 亏本 | B6: 4 | C6: =(社保费用计算表!C12*12)*(1+社保费用计算表!D13)^每年金额计算!B6 -> 18868.03 | D6: =SUM($C$3:C6) -> 72238.353 | E6: 4 | F6: =(社保费用计算表!D15*12)*(1+社保费用计算表!G15)^每年金额计算!E6 -> 20782.697 | G6: =SUM($F$3:F6) -> 80717.571
A7: =IF(G7>社保费用计算表!D14,"回本","亏本") -> 亏本 | B7: 5 | C7: =(社保费用计算表!C12*12)*(1+社保费用计算表!D13)^每年金额计算!B7 -> 19434.071 | D7: =SUM($C$3:C7) -> 91672.423 | E7: 5 | F7: =(社保费用计算表!D15*12)*(1+社保费用计算表!G15)^每年金额计算!E7 -> 21198.351 | G7: =SUM($F$3:F7) -> 101915.92
A8: =IF(G8>社保费用计算表!D14,"回本","亏本") -> 亏本 | B8: 6 | C8: =(社保费用计算表!C12*12)*(1+社保费用计算表!D13)^每年金额计算!B8 -> 20017.093 | D8: =SUM($C$3:C8) -> 111689.52 | E8: 6 | F8: =(社保费用计算表!D15*12)*(1+社保费用计算表!G15)^每年金额计算!E8 -> 21622.318 | G8: =SUM($F$3:F8) -> 123538.24
A9: =IF(G9>社保费用计算表!D14,"回本","亏本") -> 亏本 | B9: 7 | C9: =(社保费用计算表!C12*12)*(1+社保费用计算表!D13)^每年金额计算!B9 -> 20617.605 | D9: =SUM($C$3:C9) -> 132307.12 | E9: 7 | F9: =(社保费用计算表!D15*12)*(1+社保费用计算表!G15)^每年金额计算!E9 -> 22054.765 | G9: =SUM($F$3:F9) -> 145593.01
A10: =IF(G10>社保费用计算表!D14,"回本","亏本") -> 亏本 | B10: 8 | C10: =(社保费用计算表!C12*12)*(1+社保费用计算表!D13)^每年金额计算!B10 -> 21236.134 | D10: =SUM($C$3:C10) -> 153543.26 | E10: 8 | F10: =(社保费用计算表!D15*12)*(1+社保费用计算表!G15)^每年金额计算!E10 -> 22495.86 | G10: =SUM($F$3:F10) -> 168088.87
A11: =IF(G11>社保费用计算表!D14,"回本","亏本") -> 亏本 | B11: 9 | C11: =(社保费用计算表!C12*12)*(1+社保费用计算表!D13)^每年金额计算!B11 -> 21873.218 | D11: =SUM($C$3:C11) -> 175416.47 | E11: 9 | F11: =(社保费用计算表!D15*12)*(1+社保费用计算表!G15)^每年金额计算!E11 -> 22945.777 | G11: =SUM($F$3:F11) -> 191034.64
A12: =IF(G12>社保费用计算表!D14,"回本","亏本") -> 亏本 | B12: 10 | C12: =(社保费用计算表!C12*12)*(1+社保费用计算表!D13)^每年金额计算!B12 -> 22529.414 | D12: =SUM($C$3:C12) -> 197945.89 | E12: 10 | F12: =(社保费用计算表!D15*12)*(1+社保费用计算表!G15)^每年金额计算!E12 -> 23404.693 | G12: =SUM($F$3:F12) -> 214439.34
A13: =IF(G13>社保费用计算表!D14,"回本","亏本") -> 亏本 | B13: 11 | C13: =(社保费用计算表!C12*12)*(1+社保费用计算表!D13)^每年金额计算!B13 -> 23205.297 | D13: =SUM($C$3:C13) -> 221151.18 | E13: 11 | F13: =(社保费用计算表!D15*12)*(1+社保费用计算表!G15)^每年金额计算!E13 -> 23872.787 | G13: =SUM($F$3:F13) -> 238312.12
A14: =IF(G14>社保费用计算表!D14,"回本","亏本") -> 亏本 | B14: 12 | C14: =(社保费用计算表!C12*12)*(1+社保费用计算表!D13)^每年金额计算!B14 -> 23901.456 | D14: =SUM($C$3:C14) -> 245052.64 | E14: 12 | F14: =(社保费用计算表!D15*12)*(1+社保费用计算表!G15)^每年金额计算!E14 -> 24350.242 | G14: =SUM($F$3:F14) -> 262662.37
A15: =IF(G15>社保费用计算表!D14,"回本","亏本") -> 亏本 | B15: 13 | C15: =(社保费用计算表!C12*12)*(1+社保费用计算表!D13)^每年金额计算!B15 -> 24618.499 | D15: =SUM($C$3:C15) -> 269671.14 | E15: 13 | F15: =(社保费用计算表!D15*12)*(1+社保费用计算表!G15)^每年金额计算!E15 -> 24837.247 | G15: =SUM($F$3:F15) -> 287499.61
A16: =IF(G16>社保费用计算表!D14,"回本","亏本") -> 亏本 | B16: 14 | C16: =(社保费用计算表!C12*12)*(1+社保费用计算表!D13)^每年金额计算!B16 -> 25357.054 | D16: =SUM($C$3:C16) -> 295028.19 | E16: 14 | F16: =(社保费用计算表!D15*12)*(1+社保费用计算表!G15)^每年金额计算!E16 -> 25333.992 | G16: =SUM($F$3:F16) -> 312833.6
A17: =IF(G17>社保费用计算表!D14,"回本","亏本") -> 亏本 | B17: 15 | C17: =(社保费用计算表!C12*12)*(1+社保费用计算表!D13)^每年金额计算!B17 -> 26117.766 | D17: =SUM($C$3:C17) -> 321145.96 | E17: 15 | F17: =(社保费用计算表!D15*12)*(1+社保费用计算表!G15)^每年金额计算!E17 -> 25840.672 | G17: =SUM($F$3:F17) -> 338674.28
A18: =IF(G18>社保费用计算表!D14,"回本","亏本") -> 亏本 | B18: 16 | C18: =(社保费用计算表!C12*12)*(1+社保费用计算表!D13)^每年金额计算!B18 -> 26901.299 | D18: =SUM($C$3:C18) -> 348047.26 | E18: 16 | F18: =(社保费用计算表!D15*12)*(1+社保费用计算表!G15)^每年金额计算!E18 -> 26357.486 | G18: =SUM($F$3:F18) -> 365031.76
A19: =IF(G19>社保费用计算表!D14,"回本","亏本") -> 亏本 | B19: 17 | C19: =(社保费用计算表!C12*12)*(1+社保费用计算表!D13)^每年金额计算!B19 -> 27708.338 | D19: =SUM($C$3:C19) -> 375755.59 | E19: 17 | F19: =(社保费用计算表!D15*12)*(1+社保费用计算表!G15)^每年金额计算!E19 -> 26884.635 | G19: =SUM($F$3:F19) -> 391916.4
A20: =IF(G20>社保费用计算表!D14,"回本","亏本") -> 亏本 | B20: 18 | C20: =(社保费用计算表!C12*12)*(1+社保费用计算表!D13)^每年金额计算!B20 -> 28539.588 | D20: =SUM($C$3:C20) -> 404295.18 | E20: 18 | F20: =(社保费用计算表!D15*12)*(1+社保费用计算表!G15)^每年金额计算!E20 -> 27422.328 | G20: =SUM($F$3:F20) -> 419338.73
A21: =IF(G21>社保费用计算表!D14,"回本","亏本") -> 亏本 | B21: 19 | C21: =(社保费用计算表!C12*12)*(1+社保费用计算表!D13)^每年金额计算!B21 -> 29395.775 | D21: =SUM($C$3:C21) -> 433690.96 | E21: 19 | F21: =(社保费用计算表!D15*12)*(1+社保费用计算表!G15)^每年金额计算!E21 -> 27970.775 | G21: =SUM($F$3:F21) -> 447309.5
A22: =IF(G22>社保费用计算表!D14,"回本","亏本") -> 回本 | B22: 20 | C22: =(社保费用计算表!C12*12)*(1+社保费用计算表!D13)^每年金额计算!B22 -> 30277.649 | D22: =SUM($C$3:C22) -> 463968.61 | E22: 20 | F22: =(社保费用计算表!D15*12)*(1+社保费用计算表!G15)^每年金额计算!E22 -> 28530.19 | G22: =SUM($F$3:F22) -> 475839.69
A23: =IF(G23>社保费用计算表!D14,"回本","亏本") -> 回本 | B23: 21 | C23: =(社保费用计算表!C12*12)*(1+社保费用计算表!D13)^每年金额计算!B23 -> 31185.978 | D23: =SUM($C$3:C23) -> 495154.58 | E23: 21 | F23: =(社保费用计算表!D15*12)*(1+社保费用计算表!G15)^每年金额计算!E23 -> 29100.794 | G23: =SUM($F$3:F23) -> 504940.48
A24: =IF(G24>社保费用计算表!D14,"回本","亏本") -> 回本 | B24: 22 | C24: =(社保费用计算表!C12*12)*(1+社保费用计算表!D13)^每年金额计算!B24 -> 32121.558 | D24: =SUM($C$3:C24) -> 527276.14 | E24: 22 | F24: =(社保费用计算表!D15*12)*(1+社保费用计算表!G15)^每年金额计算!E24 -> 29682.81 | G24: =SUM($F$3:F24) -> 534623.29
A25: =IF(G25>社保费用计算表!D14,"回本","亏本") -> 回本 | B25: 23 | C25: =(社保费用计算表!C12*12)*(1+社保费用计算表!D13)^每年金额计算!B25 -> 33085.204 | D25: =SUM($C$3:C25) -> 560361.35 | E25: 23 | F25: =(社保费用计算表!D15*12)*(1+社保费用计算表!G15)^每年金额计算!E25 -> 30276.466 | G25: =SUM($F$3:F25) -> 564899.76
A26: =IF(G26>社保费用计算表!D14,"回本","亏本") -> 回本 | B26: 24 | C26: =(社保费用计算表!C12*12)*(1+社保费用计算表!D13)^每年金额计算!B26 -> 34077.76 | D26: =SUM($C$3:C26) -> 594439.11 | E26: 24 | F26: =(社保费用计算表!D15*12)*(1+社保费用计算表!G15)^每年金额计算!E26 -> 30881.995 | G26: =SUM($F$3:F26) -> 595781.75
A27: =IF(G27>社保费用计算表!D14,"回本","亏本") -> 回本 | B27: 25 | C27: =(社保费用计算表!C12*12)*(1+社保费用计算表!D13)^每年金额计算!B27 -> 35100.093 | D27: =SUM($C$3:C27) -> 629539.2 | E27: 25 | F27: =(社保费用计算表!D15*12)*(1+社保费用计算表!G15)^每年金额计算!E27 -> 31499.635 | G27: =SUM($F$3:F27) -> 627281.39
A28: =IF(G28>社保费用计算表!D14,"回本","亏本") -> 回本 | B28: 26 | C28: =(社保费用计算表!C12*12)*(1+社保费用计算表!D13)^每年金额计算!B28 -> 36153.096 | D28: =SUM($C$3:C28) -> 665692.3 | E28: 26 | F28: =(社保费用计算表!D15*12)*(1+社保费用计算表!G15)^每年金额计算!E28 -> 32129.628 | G28: =SUM($F$3:F28) -> 659411.02
A29: =IF(G29>社保费用计算表!D14,"回本","亏本") -> 回本 | B29: 27 | C29: =(社保费用计算表!C12*12)*(1+社保费用计算表!D13)^每年金额计算!B29 -> 37237.689 | D29: =SUM($C$3:C29) -> 702929.99 | E29: 27 | F29: =(社保费用计算表!D15*12)*(1+社保费用计算表!G15)^每年金额计算!E29 -> 32772.22 | G29: =SUM($F$3:F29) -> 692183.24
A30: =IF(G30>社保费用计算表!D14,"回本","亏本") -> 回本 | B30: 28 | C30: =(社保费用计算表!C12*12)*(1+社保费用计算表!D13)^每年金额计算!B30 -> 38354.82 | D30: =SUM($C$3:C30) -> 741284.8 | E30: 28 | F30: =(社保费用计算表!D15*12)*(1+社保费用计算表!G15)^每年金额计算!E30 -> 33427.665 | G30: =SUM($F$3:F30) -> 725610.9
A31: =IF(G31>社保费用计算表!D14,"回本","亏本") -> 回本 | B31: 29 | C31: =(社保费用计算表!C12*12)*(1+社保费用计算表!D13)^每年金额计算!B31 -> 39505.464 | D31: =SUM($C$3:C31) -> 780790.27 | E31: 29 | F31: =(社保费用计算表!D15*12)*(1+社保费用计算表!G15)^每年金额计算!E31 -> 34096.218 | G31: =SUM($F$3:F31) -> 759707.12
A32: =IF(G32>社保费用计算表!D14,"回本","亏本") -> 回本 | B32: 30 | C32: =(社保费用计算表!C12*12)*(1+社保费用计算表!D13)^每年金额计算!B32 -> 40690.628 | D32: =SUM($C$3:C32) -> 821480.9 | E32: 30 | F32: =(社保费用计算表!D15*12)*(1+社保费用计算表!G15)^每年金额计算!E32 -> 34778.142 | G32: =SUM($F$3:F32) -> 794485.26
A33: =IF(G33>社保费用计算表!D14,"回本","亏本") -> 回本 | B33: 31 | C33: =(社保费用计算表!C12*12)*(1+社保费用计算表!D13)^每年金额计算!B33 -> 41911.347 | D33: =SUM($C$3:C33) -> 863392.24 | E33: 31 | F33: =(社保费用计算表!D15*12)*(1+社保费用计算表!G15)^每年金额计算!E33 -> 35473.705 | G33: =SUM($F$3:F33) -> 829958.97
A34: =IF(G34>社保费用计算表!D14,"回本","亏本") -> 回本 | B34: 32 | C34: =(社保费用计算表!C12*12)*(1+社保费用计算表!D13)^每年金额计算!B34 -> 43168.687 | D34: =SUM($C$3:C34) -> 906560.93 | E34: 32 | F34: =(社保费用计算表!D15*12)*(1+社保费用计算表!G15)^每年金额计算!E34 -> 36183.179 | G34: =SUM($F$3:F34) -> 866142.15
A35: =IF(G35>社保费用计算表!D14,"回本","亏本") -> 回本 | B35: 33 | C35: =(社保费用计算表!C12*12)*(1+社保费用计算表!D13)^每年金额计算!B35 -> 44463.748 | D35: =SUM($C$3:C35) -> 951024.68 | E35: 33 | F35: =(社保费用计算表!D15*12)*(1+社保费用计算表!G15)^每年金额计算!E35 -> 36906.843 | G35: =SUM($F$3:F35) -> 903048.99
A36: =IF(G36>社保费用计算表!D14,"回本","亏本") -> 回本 | B36: 34 | C36: =(社保费用计算表!C12*12)*(1+社保费用计算表!D13)^每年金额计算!B36 -> 45797.66 | D36: =SUM($C$3:C36) -> 996822.34 | E36: 34 | F36: =(社保费用计算表!D15*12)*(1+社保费用计算表!G15)^每年金额计算!E36 -> 37644.98 | G36: =SUM($F$3:F36) -> 940693.97
A37: =IF(G37>社保费用计算表!D14,"回本","亏本") -> 回本 | B37: 35 | C37: =(社保费用计算表!C12*12)*(1+社保费用计算表!D13)^每年金额计算!B37 -> 47171.59 | D37: =SUM($C$3:C37) -> 1043993.9 | E37: 35 | F37: =(社保费用计算表!D15*12)*(1+社保费用计算表!G15)^每年金额计算!E37 -> 38397.879 | G37: =SUM($F$3:F37) -> 979091.85
A38: =IF(G38>社保费用计算表!D14,"回本","亏本") -> 回本 | B38: 36 | C38: =(社保费用计算表!C12*12)*(1+社保费用计算表!D13)^每年金额计算!B38 -> 48586.738 | D38: =SUM($C$3:C38) -> 1092580.7 | E38: 36 | F38: =(社保费用计算表!D15*12)*(1+社保费用计算表!G15)^每年金额计算!E38 -> 39165.837 | G38: =SUM($F$3:F38) -> 1018257.7
A39: =IF(G39>社保费用计算表!D14,"回本","亏本") -> 回本 | B39: 37 | C39: =(社保费用计算表!C12*12)*(1+社保费用计算表!D13)^每年金额计算!B39 -> 50044.34 | D39: =SUM($C$3:C39) -> 1142625 | E39: 37 | F39: =(社保费用计算表!D15*12)*(1+社保费用计算表!G15)^每年金额计算!E39 -> 39949.154 | G39: =SUM($F$3:F39) -> 1058206.8
A40: =IF(G40>社保费用计算表!D14,"回本","亏本") -> 回本 | B40: 38 | C40: =(社保费用计算表!C12*12)*(1+社保费用计算表!D13)^每年金额计算!B40 -> 51545.67 | D40: =SUM($C$3:C40) -> 1194170.7 | E40: 38 | F40: =(社保费用计算表!D15*12)*(1+社保费用计算表!G15)^每年金额计算!E40 -> 40748.137 | G40: =SUM($F$3:F40) -> 1098955
...
